{"author":{"id":"8280890c639b421e6b9dcf2035bdf915ac11c1cf0e1f9dd00b2f6437faa22719"},"ops":[{"type":6,"timestamp":1586548065,"nonce":"1xhypXYo5m7eWi3X36ktHBP6ZEE=","metadata":{"github-id":"MDE1OlVzZXJDb250ZW50RWRpdElzc3VlRWRpdDozNjk3MTQ2ODU="},"target":"07f75ef2824dc7883f9a1b9c4364811506ea7dc844a42a33fb27352d4335c1b8","message":"Hi,\n\nPlaying with git-bug on a existing gitlab repository with a few existing issues on the vendor's bug tracker,  I ran trough the following errors:\n\nAfter having successfully configured the bridge I could import the gitlab issues as well as creating a couple of local issues with `git bug add`, so far so good. Then, I meet the following errors:\n* when doing again `git bug bridge pull`, issues are duplicated with new hashes. \n* nothing is exported when doing `git bug bridge push`.\n\nI've tested the bridge on a freshly created repo on gitlab, again the first steps goes well, but this time when doing `git bug bridge` a second time to test if duplicates arise, I got this crash:\n\n```\npanic: runtime error: index out of range [-1]                                                                                                        \n                                                                        \ngoroutine 51 [running]:       \ngithub.com/MichaelMure/git-bug/bridge/gitlab/iterator.(*issueIterator).Value(...)\n        /home/dtrckd/src/_sink/git-bug/bridge/gitlab/iterator/issue.go:38\ngithub.com/MichaelMure/git-bug/bridge/gitlab/iterator.(*Iterator).NextIssue(0xc0010ba000, 0xc000043dd0)\n        /home/dtrckd/src/_sink/git-bug/bridge/gitlab/iterator/iterator.go:86 +0x244\ngithub.com/MichaelMure/git-bug/bridge/gitlab.(*gitlabImporter).ImportAll.func1(0xc000260100, 0xc0000aed00, 0xc0010bc000)\n        /home/dtrckd/src/_sink/git-bug/bridge/gitlab/import.go:70 +0x547\ncreated by github.com/MichaelMure/git-bug/bridge/gitlab.(*gitlabImporter).ImportAll\n        /home/dtrckd/src/_sink/git-bug/bridge/gitlab/import.go:66 +0x146\n\n```\nSimilar scenario on Github seems to work fine.\n\nVersion:\ngit-bug version: 0.7.1-dev-28c3ee3b71\ngithub.com/xanzy/go-gitlab v0.29.0\ngo version go1.14.1 linux/amd64\n\nGitlab: 12.9.2 (self hosted)\nOS: Linux 4.19.0-8-amd64 / Debian 10 x86_64","files":null},{"type":6,"timestamp":1586548210,"nonce":"etATQt8L0RpexnVKtRnC2Mz8P/E=","metadata":{"github-id":"MDE1OlVzZXJDb250ZW50RWRpdElzc3VlRWRpdDozNjk3MTUyNDE="},"target":"07f75ef2824dc7883f9a1b9c4364811506ea7dc844a42a33fb27352d4335c1b8","message":"Hi,\n\nPlaying with git-bug on a existing gitlab repository with a few existing issues on the vendor's bug tracker,  I ran trough the following errors:\n\nAfter having successfully configured the bridge I could import the gitlab issues as well as creating a couple of local issues with `git bug add`, so far so good. Then, I meet the following errors:\n* when doing again `git bug bridge pull`, issues are duplicated with new hashes. \n* nothing is exported when doing `git bug bridge push`, it jus returns `exported 0 issues with myBridge bridge`.\n\nI've tested the bridge on a freshly created repo on gitlab, again the first steps goes well, but this time when doing `git bug bridge` a second time to test if duplicates arise, I got this crash:\n\n```\npanic: runtime error: index out of range [-1]                                                                                                        \n                                                                        \ngoroutine 51 [running]:       \ngithub.com/MichaelMure/git-bug/bridge/gitlab/iterator.(*issueIterator).Value(...)\n        /home/dtrckd/src/_sink/git-bug/bridge/gitlab/iterator/issue.go:38\ngithub.com/MichaelMure/git-bug/bridge/gitlab/iterator.(*Iterator).NextIssue(0xc0010ba000, 0xc000043dd0)\n        /home/dtrckd/src/_sink/git-bug/bridge/gitlab/iterator/iterator.go:86 +0x244\ngithub.com/MichaelMure/git-bug/bridge/gitlab.(*gitlabImporter).ImportAll.func1(0xc000260100, 0xc0000aed00, 0xc0010bc000)\n        /home/dtrckd/src/_sink/git-bug/bridge/gitlab/import.go:70 +0x547\ncreated by github.com/MichaelMure/git-bug/bridge/gitlab.(*gitlabImporter).ImportAll\n        /home/dtrckd/src/_sink/git-bug/bridge/gitlab/import.go:66 +0x146\n\n```\nSimilar scenario on Github seems to work fine.\n\nVersion:\ngit-bug version: 0.7.1-dev-28c3ee3b71\ngithub.com/xanzy/go-gitlab v0.29.0\ngo version go1.14.1 linux/amd64\n\nGitlab: 12.9.2 (self hosted)\nOS: Linux 4.19.0-8-amd64 / Debian 10 x86_64","files":null},{"type":6,"timestamp":1586609211,"nonce":"rnZKCQWCjhbtQREIRP3is0uGLng=","metadata":{"github-id":"MDE1OlVzZXJDb250ZW50RWRpdElzc3VlRWRpdDozNjk4MzA1ODM="},"target":"07f75ef2824dc7883f9a1b9c4364811506ea7dc844a42a33fb27352d4335c1b8","message":"Hi,\n\nPlaying with git-bug on a existing gitlab repository with a few existing issues on the vendor's bug tracker,  I ran trough the following errors:\n\nAfter having successfully configured the bridge I could import the gitlab issues as well as creating a couple of local issues with `git bug add`, so far so good. Then, I meet the following errors:\n* when doing again `git bug bridge pull`, issues are duplicated with new hashes. \n* nothing is exported when doing `git bug bridge push`, it jus returns `exported 0 issues with myBridge bridge`.\n\nI've tested the bridge on a freshly created repo on gitlab, again the first steps goes well, but this time when doing `git bug bridge pull` a second time to test if duplicates arise, I got this crash:\n\n```\npanic: runtime error: index out of range [-1]                                                                                                        \n                                                                        \ngoroutine 51 [running]:       \ngithub.com/MichaelMure/git-bug/bridge/gitlab/iterator.(*issueIterator).Value(...)\n        /home/dtrckd/src/_sink/git-bug/bridge/gitlab/iterator/issue.go:38\ngithub.com/MichaelMure/git-bug/bridge/gitlab/iterator.(*Iterator).NextIssue(0xc0010ba000, 0xc000043dd0)\n        /home/dtrckd/src/_sink/git-bug/bridge/gitlab/iterator/iterator.go:86 +0x244\ngithub.com/MichaelMure/git-bug/bridge/gitlab.(*gitlabImporter).ImportAll.func1(0xc000260100, 0xc0000aed00, 0xc0010bc000)\n        /home/dtrckd/src/_sink/git-bug/bridge/gitlab/import.go:70 +0x547\ncreated by github.com/MichaelMure/git-bug/bridge/gitlab.(*gitlabImporter).ImportAll\n        /home/dtrckd/src/_sink/git-bug/bridge/gitlab/import.go:66 +0x146\n\n```\nSimilar scenario on Github seems to work fine.\n\nVersion:\ngit-bug version: 0.7.1-dev-28c3ee3b71\ngithub.com/xanzy/go-gitlab v0.29.0\ngo version go1.14.1 linux/amd64\n\nGitlab: 12.9.2 (self hosted)\nOS: Linux 4.19.0-8-amd64 / Debian 10 x86_64","files":null},{"type":3,"timestamp":1586562076,"nonce":"3R7uuxAmro7/sl5jD7/pTWAXjhQ=","metadata":{"github-id":"MDEyOklzc3VlQ29tbWVudDYxMjI2NzQ0Mg==","github-url":"https://github.com/git-bug/git-bug/issues/366#issuecomment-612267442"},"message":"New test result: \nWhen using git-bug bridge by pushing bug to remote first, it works. Then If we create an issue on Gitlab and import it, the same scenario as before, firts time ok, then I got the crash (+ the doublon), and bridge push doesn't push new local bug anymore.","files":null},{"type":6,"timestamp":1586609409,"nonce":"8aLCnigHCGuZlp/WpHctT8VGIC8=","metadata":{"github-id":"MDE1OlVzZXJDb250ZW50RWRpdElzc3VlQ29tbWVudEVkaXQ6MzY0NTI2NjQ2"},"target":"7814b2ff424c827a8d88b9f5e8e3f57fa8fd314307fdaf3fe13f73a9d18fc205","message":"New test result: \nWhen using git-bug bridge by pushing bugs to remote **before** pulling, bug are exported. Then If we create an issue on Gitlab and import, the first time import is ok, then I got the crash (+ the doublon), and bridge push doesn't push new local bug anymore.","files":null}]}