{"author":{"id":"4d85ccdde3ad47c902de21b580354b67ed0cb07caa04e32d04ea93112f7f027e"},"ops":[{"type":1,"timestamp":1721540370,"nonce":"o3UNS+TSMCjhmSIIw0/C2qO2rZQ=","metadata":{"github-id":"I_kwDOCGKeh86QURRd","github-url":"https://github.com/git-bug/git-bug/issues/1194","origin":"github"},"title":"flaky test: //cache/repo_cache_test.go%TestCache","message":"```\n=== RUN   TestCache\n    repo_cache_test.go:163: \n        \tError Trace:\tD:/a/git-bug/git-bug/cache/repo_cache_test.go:163\n        \tError:      \tReceived unexpected error:\n        \t            \tremove C:\\Users\\RUNNER~1\\AppData\\Local\\Temp\\TestCache1576603400\\001\\.git\\refs\\bugs\\6cc51bbddc3c2a6de7c8effacd3766e2ea7935a6a3fee9a4f46af3ea846921d0: The process cannot access the file because it is being used by another process.\n        \tTest:       \tTestCache\n```\n\n_Sourced from: https://github.com/MichaelMure/git-bug/actions/runs/10024586195/job/27706826825#step:5:196_","files":null}]}