{"author":{"id":"b5973ae855e2f905b456b1d013421c6a4bcb12d1c11fd04c08cfc5248651f7e1"},"ops":[{"type":3,"timestamp":1586745192,"nonce":"cGnBaKZHFh+E+2zd+Sn/AgRMgds=","metadata":{"github-id":"MDEyOklzc3VlQ29tbWVudDYxMjcyMTY3OQ==","github-url":"https://github.com/git-bug/git-bug/issues/366#issuecomment-612721679"},"message":"I've received this error as well. Create an identity locally, then followed these steps:\n\n1. `git bug bridge configure` - set up gitlab as the bridge\n2. \n```\ngit bug bridge push\nnew issue: e80238b17c133382dc01ba74eef316ad50d84e5c\nexported 1 issues with gitlab bridge\n```\n3. Made a change in the Gitlab UI (applied a label to the issue).\n4.\n```\ngit bug bridge pull\nnew identity: 7cef8e713b2299d8a8035d038c42d5c29e75cda9\nnew issue: 0d4041eb258226f712c9391835e7faf409792dc9\nimported 1 issues and 1 identities with gitlab bridge\n```\n5. `git bug termui` - notice that there are now two issues listed, one with the label, one without.\n6. \n```\ngit bug bridge pull\npanic: runtime error: index out of range [-1]\n\ngoroutine 57 [running]:\ngithub.com/MichaelMure/git-bug/bridge/gitlab/iterator.(*issueIterator).Value(...)\n\t/home/travis/gopath/src/github.com/MichaelMure/git-bug/bridge/gitlab/iterator/issue.go:38\ngithub.com/MichaelMure/git-bug/bridge/gitlab/iterator.(*Iterator).NextIssue(0xc000296000, 0x0)\n\t/home/travis/gopath/src/github.com/MichaelMure/git-bug/bridge/gitlab/iterator/iterator.go:86 +0x244\ngithub.com/MichaelMure/git-bug/bridge/gitlab.(*gitlabImporter).ImportAll.func1(0xc0002541c0, 0xc000142d80, 0xc00008c1e0)\n\t/home/travis/gopath/src/github.com/MichaelMure/git-bug/bridge/gitlab/import.go:70 +0x560\ncreated by github.com/MichaelMure/git-bug/bridge/gitlab.(*gitlabImporter).ImportAll\n\t/home/travis/gopath/src/github.com/MichaelMure/git-bug/bridge/gitlab/import.go:66 +0x146\n```\n\n\nPerforming a pull from within `git bug termui` \"works,\" in that `done` is reported.","files":null},{"type":3,"timestamp":1586787014,"nonce":"1EaExc6UdzJ2/wLY0FbkDKYSMtI=","metadata":{"github-id":"MDEyOklzc3VlQ29tbWVudDYxMjkxNDMyMg==","github-url":"https://github.com/git-bug/git-bug/issues/366#issuecomment-612914322"},"message":"This also seems to affect new instances of a gitlab bridge. After configuring in another repo, I attempted to `git bug bridge pull` and received the same `panic` as above.","files":null}]}