{"author":{"id":"b28efb317feee13040279a0ffe6f4f75e52aeb67cc6adc8cc43cb1e475d5e981"},"ops":[{"type":3,"timestamp":1589748771,"nonce":"yX8rYtAmc4aCs0c6yypvE1UlXIU=","metadata":{"github-id":"MDEyOklzc3VlQ29tbWVudDYyOTg1ODk0OQ==","github-url":"https://github.com/git-bug/git-bug/issues/366#issuecomment-629858949"},"message":"Hi, I am receiving the same `panic: runtime error: index out of range [-1]` on the repo that I used for testing in #360.\n\nFor reference:\n* I used git-bug 0.7.0 on https://gitlab.com/mkroehnert/git-bug-issue-test/-/issues (which had the label issue).\n* I ran `git bug bridge pull` with git-bug 0.7.1 on the same checkout that held the initial `git bug bridge pull` from the above mentioned ticket.\n* The exact error received after the bridge pull is (same as in the very first message):\n```\npanic: runtime error: index out of range [-1]\n\ngoroutine 23 [running]:\ngithub.com/MichaelMure/git-bug/bridge/gitlab/iterator.(*issueIterator).Value(...)\n        /build/source/bridge/gitlab/iterator/issue.go:38\ngithub.com/MichaelMure/git-bug/bridge/gitlab/iterator.(*Iterator).NextIssue(0xc0000ae180, 0x0)\n        /build/source/bridge/gitlab/iterator/iterator.go:86 +0x244\ngithub.com/MichaelMure/git-bug/bridge/gitlab.(*gitlabImporter).ImportAll.func1(0xc0002161c0, 0xc0000aed00, 0xc00021c5a0)\n        /build/source/bridge/gitlab/import.go:70 +0x547\ncreated by github.com/MichaelMure/git-bug/bridge/gitlab.(*gitlabImporter).ImportAll\n        /build/source/bridge/gitlab/import.go:66 +0x146\n```","files":null}]}